<?xml version="1.0"?>
<robot name="irp6"
       xmlns:sensor="http://playerstage.sourceforge.net/gazebo/xmlschema/#sensor"
       xmlns:controller="http://playerstage.sourceforge.net/gazebo/xmlschema/#controller"
       xmlns:xacro="http://ros.org/wiki/fixme"
       xmlns:interface="http://playerstage.sourceforge.net/gazebo/xmlschema/#interface">

  <property name="M_PI" value="3.14159"/>

  <link name="world">
    <!--<inertial>
      <mass value="0.05" />
      <origin xyz="-0.0 0.0 -10.0" />
      <inertia ixx="1.0" ixy="0.0" ixz="0.0"
               iyy="1.0" iyz="0.0"
               izz="1.0" />
    </inertial>-->

    <collision>
      <origin xyz="0 0 0.15" rpy="0 0 0" />
      <geometry>
        <box size="0.4 0.4 0.3" />
      </geometry>
    </collision>
  </link>

  <joint name="base_joint" type="fixed">
    <parent link="world"/>
    <child link="tl_base"/>
  </joint>


<link name="tl_base">
  <inertial>
    <mass value="1"/>
    <inertia ixx="100" ixy="0" ixz="0" iyy="100" iyz="0" izz="100" />
    <origin xyz="0 0 0"/>
  </inertial>
  <visual>
    <origin xyz="0 .6045 .125" />
    <geometry>
      <box size=".462 1.609 .25" />
    </geometry>
    <material name="gray">
      <color rgba=".2 .2 .2 1" />
    </material>
  </visual>

  <collision>
    <origin xyz="0 .6045 .07" />
    <geometry>
      <box size=".462 1.609 .2" />
    </geometry>
  </collision>
</link>

<link name="tl_t">
  <inertial>
    <mass value="1"/>
    <inertia ixx="100" ixy="0" ixz="0" iyy="100" iyz="0" izz="100" />
    <origin xyz="0 0 0"/>
  </inertial>
  <visual>
    <origin xyz="0 0 0.075" />
    <geometry>
      <box size="0.4 0.4 0.15" />
    </geometry>
    <material name="gray">
      <color rgba=".2 .2 .2 1" />
    </material>
  </visual>

  <collision>
    <origin xyz="0 0 0" />
    <geometry>
      <box size=".0 .0 .0" />
    </geometry>
  </collision>
</link>


<joint name="Irp6otmJoint1" type="prismatic">
  <parent link="tl_base"/>
  <child link="tl_t"/>
  <origin xyz="0 0 .25" rpy="0 0 0" />
  <axis xyz="0 1 0" />
  <limit upper="1.209" lower="0" effort="10" velocity=".53" />
</joint>


  <joint name="Irp6otmJoint2" type="revolute">
    <origin rpy="0 0 0" xyz="0.0 0.0 0.3"/>
    <axis xyz="0 0 1"/>
    <limit lower="-2.96705973" upper="2.96705973" effort="10.0" velocity="10.0" />
    <parent link="tl_t"/>
    <child link="tl_1"/>
  </joint>

  <link name="tl_1">
    <inertial>
      <mass value="0.1"/>
      <origin xyz="0.0 0.0 0.0"/>
      <inertia ixx="0.1" ixy="0" ixz="0" iyy="0.1" iyz="0" izz="0.1"/>
    </inertial>

    <visual>
      <origin rpy="-1.57 0 0.0" xyz="0 0 0.4"/>
      <geometry>
        <mesh filename="package://irp6_description/meshes/link1.3ds" />
      </geometry>
    </visual>

    <collision>
      <origin rpy="-1.57 0 0.0" xyz="0 0 0.4"/>
      <geometry>
        <!--<mesh filename="package://irp6_description/meshes/link1.stlb" />-->
	<box size="0.1 0.10 0.1"/>
      </geometry>
    </collision>
  </link>

  <joint name="Irp6otmJoint3" type="revolute">
    <origin rpy="-1.570795 0 0" xyz="0.0 0.0 0.4"/>
    <axis xyz="0 0 1"/>
    <limit lower="-1.8" upper="-0.872664626" effort="10.0" velocity="10.0" />
    <parent link="tl_1"/>
    <child link="tl_2"/>
  </joint>

  <link name="tl_2">
    <inertial>
      <mass value="0.1"/>
      <origin xyz="0.0 0.0 0.0"/>
      <inertia ixx="0.1" ixy="0" ixz="0" iyy="0.1" iyz="0" izz="0.1"/>
    </inertial>

    <visual>
      <origin rpy="0 0 0.0" xyz="0.455 0.0 0.0"/>
      <geometry>
        <mesh filename="package://irp6_description/meshes/link2.3ds" />
      </geometry>
    </visual>

    <collision>
      <origin rpy="0 0 0.0" xyz="0.2 0.0 0.0"/>
      <geometry>
        <box size="0.4 0.10 0.2"/>
      </geometry>
    </collision>
  </link>



  <joint name="Irp6otmJoint4" type="revolute">
    <origin rpy="0 0 0.0" xyz="0.455 0.0 0.0"/>
    <axis xyz="0 0 1"/>
    <limit lower="-0.3" upper="0.5" effort="10.0" velocity="10.0" />
    <parent link="tl_2"/>
    <child link="tl_3"/>
  </joint>

  <link name="tl_3">
    <inertial>
      <mass value="0.1"/>
      <origin xyz="0.0 0.0 0.0"/>
      <inertia ixx="0.1" ixy="0" ixz="0" iyy="0.1" iyz="0" izz="0.1"/>
    </inertial>

    <visual>
      <origin rpy="0 0 1.57" xyz="0 0.67 0.0"/>
      <geometry>
        <mesh filename="package://irp6_description/meshes/link3.3ds" />
      </geometry>
    </visual>

    <collision>
      <origin rpy="0 0 1.57" xyz="0 0.67 0.0"/>
      <geometry>
        <mesh filename="package://irp6_description/meshes/link3.stlb" scale="1.0 1.0 1.3" />
      </geometry>
    </collision>
  </link>


  <joint name="Irp6otmJoint5" type="revolute">
    <origin rpy="0 0 0" xyz="0.0 0.67 0.0"/>
    <axis xyz="0 0 1"/>
    <limit lower="-1.57" upper="1.57" effort="10.0" velocity="10.0" />
    <parent link="tl_3"/>
    <child link="tl_4"/>
  </joint>

  <link name="tl_4">
    <inertial>
      <mass value="0.1"/>
      <origin xyz="0.0 0.0 0.0"/>
      <inertia ixx="0.1" ixy="0" ixz="0" iyy="0.1" iyz="0" izz="0.1"/>
    </inertial>

    <visual>
      <origin rpy="1.57 0 1.57" xyz="0.0 0.175 0.0"/>
      <geometry>
        <mesh filename="package://irp6_description/meshes/link4.3ds" />
      </geometry>
    </visual>

    <collision>
      <origin rpy="1.57 0 1.57" xyz="0.0 0.175 0.0"/>
      <geometry>
        <mesh filename="package://irp6_description/meshes/link4.stlb" />
      </geometry>
    </collision>
  </link>


  <joint name="Irp6otmJoint6" type="revolute">
    <origin rpy="-1.570795 0 0" xyz="0.0 0.0 0.0"/>
    <axis xyz="0 0 1"/>
    <limit lower="-0.5" upper="5.14" effort="10.0" velocity="10.0" />
    <parent link="tl_4"/>
    <child link="tl_5"/>
  </joint>

  <link name="tl_5">
    <inertial>
      <mass value="0.1"/>
      <origin xyz="0.0 0.0 0.0"/>
      <inertia ixx="0.1" ixy="0" ixz="0" iyy="0.1" iyz="0" izz="0.1"/>
    </inertial>

    <visual>
      <origin rpy="1.57 0 0.0" xyz="0.0 0.0 0.19"/>
      <geometry>
        <mesh filename="package://irp6_description/meshes/link5.3ds" />
      </geometry>
    </visual>

    <collision>
      <origin rpy="1.57 0 0.0" xyz="0.0 0.0 0.19"/>
      <geometry>
        <mesh filename="package://irp6_description/meshes/link5.stlb" />
      </geometry>
    </collision>
  </link>


  <joint name="Irp6otmJoint7" type="revolute">
    <origin rpy="1.570795 0 0" xyz="0.0 0.0 0.19"/>
    <axis xyz="0 0 1"/>
    <limit lower="-3.0" upper="2.9" effort="10.0" velocity="10.0" />
    <parent link="tl_5"/>
    <child link="tl_6"/>
  </joint>

  <link name="tl_6">
    <inertial>
      <mass value="0.1"/>
      <origin xyz="0.0 0.0 0.0"/>
      <inertia ixx="0.1" ixy="0" ixz="0" iyy="0.1" iyz="0" izz="0.1"/>
    </inertial>

    <visual>
      <origin rpy="0 0 0.0" xyz="0 0.0 0.15"/>
      <geometry>
         <mesh filename="package://irp6_description/meshes/link6.3ds" />
      </geometry>
    </visual>

    <collision>
      <origin rpy="0.0 0 0.0" xyz="0 0.0 -0.05"/>
      <geometry>
        <cylinder radius="0.1" length="0.10" />
      </geometry>
    </collision>
  </link>



  <joint name="Irp6ottfgJoint1" type="prismatic">
    <origin rpy="0 0 0" xyz="0.0 0.0 0.15"/>
    <parent link="tl_6"/>
    <child link="tl_g1"/>
    <axis xyz="0 1 0" />
    <limit upper="0.1" lower="0" effort="10" velocity=".53" />
  </joint>


  <joint name="Irp6ottfgJoint1a" type="prismatic">
    <origin rpy="0 0 0" xyz="0.0 0.0 0.15"/>
    <parent link="tl_6"/>
    <child link="tl_g2"/>
    <axis xyz="0 -1 0" />
    <limit upper="0.1" lower="0" effort="10" velocity=".53" />
    <mimic joint="Irp6ottfgJoint1" />
  </joint>


  <link name="tl_g1">
    <inertial>
      <mass value="0.1"/>
      <origin xyz="0.0 0.0 0.0"/>
      <inertia ixx="0.1" ixy="0" ixz="0" iyy="0.1" iyz="0" izz="0.1"/>
    </inertial>

    <visual>
      <origin rpy="0 0 0.0" xyz="0 0.02 0.0"/>
      <geometry>
         <box size="0.05 0.04 0.12" />
      </geometry>
    </visual>

    <collision>
      <origin rpy="0.0 0 0.0" xyz="0 0.02 0.0"/>
      <geometry>
        <box size="0.05 0.04 0.12" />
      </geometry>
    </collision>
  </link>


<link name="tl_g2">
    <inertial>
      <mass value="0.1"/>
      <origin xyz="0.0 0.0 0.0"/>
      <inertia ixx="0.1" ixy="0" ixz="0" iyy="0.1" iyz="0" izz="0.1"/>
    </inertial>

    <visual>
      <origin rpy="0 0 0.0" xyz="0 -0.02 0.0"/>
      <geometry>
         <box size="0.05 0.04 0.12" />
      </geometry>
    </visual>

    <collision>
      <origin rpy="0.0 0 0.0" xyz="0 -0.02 0.0"/>
      <geometry>
        <box size="0.05 0.04 0.12" />
      </geometry>
    </collision>
  </link>


<joint name="tl_camera" type="fixed">
    <origin rpy="0.0 0.0 1.57" xyz="-0.0551 0.0 0.13"/>
    <parent link="tl_6"/>
    <child link="t_c"/>
  </joint>

<link name="t_c">
</link>

<joint name="tl_camera_optical_frame" type="fixed">
    <origin rpy="0.0 0.0 3.14" xyz="0 0 0"/>
    <parent link="t_c"/>
    <child link="t_c_optical_frame"/>
</joint>

<link name="t_c_optical_frame">
</link>

<joint name="t_calib_joint" type="fixed">
<!--    <origin rpy="0.0 ${M_PI/2} ${M_PI/4}" xyz="0.05 0.7 -0.05"/> -->
    <origin xyz="-0.50751 0.769 -0.016818" rpy="0.0 ${M_PI/2} ${M_PI/4}"/>
    <parent link="tl_3"/>
    <child link="t_calib_link"/>
</joint>

<link name="t_calib_link">
</link>

<joint name="tl_kinect" type="fixed">
<!--    <origin rpy="0.0 1.57 0.0" xyz="0.82 -0.2 2.08"/> -->
    <origin xyz="0.88317 -0.21239 2.0291" rpy="-2.8825 1.3979 -2.8821"/>
    <parent link="tl_base"/>
    <child link="t_kinect"/>
</joint>

<link name="t_kinect">
</link>

<joint name="tl_kinect_optical_frame" type="fixed">
    <origin xyz="0 0 0" rpy="-1.57 0.0 -1.57" />
    <parent link="t_kinect"/>
    <child link="t_kinect_optical_frame"/>
</joint>

<link name="t_kinect_optical_frame">
</link>

<!-- -.-.-.-.-.-.-.-.-.-.-.-.-.-.-.-.-.-.-.-.-.-.-.-.-.-.-.-.-.-.-.-.-.-.-.-.-.-.-.-.-.-.- -->

  <joint name="base_joint_p" type="fixed">
    <origin rpy="0 0 0.0" xyz="0.0 2.11 0.0"/>
    <parent link="world"/>
    <child link="pl_base"/>
  </joint>

  <link name="pl_base">
    <inertial>
      <mass value="0" />
      <origin xyz="-0.0 0.0 0.0" />
      <inertia ixx="1.0" ixy="0.0" ixz="0.0"
               iyy="1.0" iyz="0.0"
               izz="1.0" />
    </inertial>

    <collision>
      <origin xyz="0 0 0.15" rpy="0 0 0" />
      <geometry>
        <box size="0.4 0.4 0.3" />
      </geometry>
    </collision>
    <visual>
      <origin xyz="0 0 0.2" />
      <geometry>
        <box size="0.4 0.4 0.4" />
      </geometry>
      <material name="gray">
      <color rgba=".2 .2 .2 1" />
    </material>
  </visual>
  </link>

  <joint name="Irp6pmJoint1" type="revolute">
    <origin rpy="0 0 0" xyz="0.0 0.0 0.55"/>
    <axis xyz="0 0 1"/>
    <limit lower="-2.96705973" upper="2.96705973" effort="10.0" velocity="10.0" />
    <parent link="pl_base"/>
    <child link="pl_1"/>
  </joint>

  <link name="pl_1">
    <inertial>
      <mass value="0.1"/>
      <origin xyz="0.0 0.0 0.0"/>
      <inertia ixx="0.1" ixy="0" ixz="0" iyy="0.1" iyz="0" izz="0.1"/>
    </inertial>

    <visual>
      <origin rpy="-1.57 0 0.0" xyz="0 0 0.4"/>
      <geometry>
        <mesh filename="package://irp6_description/meshes/link1.3ds" />
      </geometry>
    </visual>

    <collision>
      <origin rpy="-1.57 0 0.0" xyz="0 0 0.4"/>
      <geometry>
        <!--<mesh filename="package://irp6_description/meshes/link1.stlb" />-->
	<box size="0.1 0.10 0.1"/>
      </geometry>
    </collision>
  </link>

  <joint name="Irp6pmJoint2" type="revolute">
    <origin rpy="-1.570795 0 0" xyz="0.0 0.0 0.4"/>
    <axis xyz="0 0 1"/>
    <limit lower="-1.8" upper="-0.872664626" effort="10.0" velocity="10.0" />
    <parent link="pl_1"/>
    <child link="pl_2"/>
  </joint>

  <link name="pl_2">
    <inertial>
      <mass value="0.1"/>
      <origin xyz="0.0 0.0 0.0"/>
      <inertia ixx="0.1" ixy="0" ixz="0" iyy="0.1" iyz="0" izz="0.1"/>
    </inertial>

    <visual>
      <origin rpy="0 0 0.0" xyz="0.455 0.0 0.0"/>
      <geometry>
        <mesh filename="package://irp6_description/meshes/link2.3ds" />
      </geometry>
    </visual>

    <collision>
      <origin rpy="0 0 0.0" xyz="0.2 0.0 0.0"/>
      <geometry>
        <box size="0.4 0.10 0.2"/>
      </geometry>
    </collision>
  </link>

  <joint name="Irp6pmJoint3" type="revolute">
    <origin rpy="0 0 0.0" xyz="0.455 0.0 0.0"/>
    <axis xyz="0 0 1"/>
    <limit lower="-0.3" upper="0.5" effort="10.0" velocity="10.0" />
    <parent link="pl_2"/>
    <child link="pl_3"/>
  </joint>

  <link name="pl_3">
    <inertial>
      <mass value="0.1"/>
      <origin xyz="0.0 0.0 0.0"/>
      <inertia ixx="0.1" ixy="0" ixz="0" iyy="0.1" iyz="0" izz="0.1"/>
    </inertial>

    <visual>
      <origin rpy="0 0 1.57" xyz="0 0.67 0.0"/>
      <geometry>
        <mesh filename="package://irp6_description/meshes/link3.3ds" />
      </geometry>
    </visual>

    <collision>
      <origin rpy="0 0 1.57" xyz="0 0.67 0.0"/>
      <geometry>
        <mesh filename="package://irp6_description/meshes/link3.stlb" scale="1.0 1.0 1.3" />
      </geometry>
    </collision>
  </link>

  <joint name="Irp6pmJoint4" type="revolute">
    <origin rpy="0 0 0" xyz="0.0 0.67 0.0"/>
    <axis xyz="0 0 1"/>
    <limit lower="-1.57" upper="1.57" effort="10.0" velocity="10.0" />
    <parent link="pl_3"/>
    <child link="pl_4"/>
  </joint>

  <link name="pl_4">
    <inertial>
      <mass value="0.1"/>
      <origin xyz="0.0 0.0 0.0"/>
      <inertia ixx="0.1" ixy="0" ixz="0" iyy="0.1" iyz="0" izz="0.1"/>
    </inertial>

    <visual>
      <origin rpy="1.57 0 1.57" xyz="0.0 0.175 0.0"/>
      <geometry>
        <mesh filename="package://irp6_description/meshes/link4.3ds" />
      </geometry>
    </visual>

    <collision>
      <origin rpy="1.57 0 1.57" xyz="0.0 0.175 0.0"/>
      <geometry>
        <mesh filename="package://irp6_description/meshes/link4.stlb" />
      </geometry>
    </collision>
  </link>

  <joint name="Irp6pmJoint5" type="revolute">
    <origin rpy="-1.570795 0 0" xyz="0.0 0.0 0.0"/>
    <axis xyz="0 0 1"/>
    <limit lower="-0.5" upper="5.14" effort="10.0" velocity="10.0" />
    <parent link="pl_4"/>
    <child link="pl_5"/>
  </joint>

  <link name="pl_5">
    <inertial>
      <mass value="0.1"/>
      <origin xyz="0.0 0.0 0.0"/>
      <inertia ixx="0.1" ixy="0" ixz="0" iyy="0.1" iyz="0" izz="0.1"/>
    </inertial>

    <visual>
      <origin rpy="1.57 0 0.0" xyz="0.0 0.0 0.19"/>
      <geometry>
        <mesh filename="package://irp6_description/meshes/link5.3ds" />
      </geometry>
    </visual>

    <collision>
      <origin rpy="1.57 0 0.0" xyz="0.0 0.0 0.19"/>
      <geometry>
        <mesh filename="package://irp6_description/meshes/link5.stlb" />
      </geometry>
    </collision>
  </link>

  <joint name="Irp6pmJoint6" type="revolute">
    <origin rpy="1.570795 0 0" xyz="0.0 0.0 0.19"/>
    <axis xyz="0 0 1"/>
    <limit lower="-3.0" upper="2.9" effort="10.0" velocity="10.0" />
    <parent link="pl_5"/>
    <child link="pl_6"/>
  </joint>

  <link name="pl_6">
    <inertial>
      <mass value="0.1"/>
      <origin xyz="0.0 0.0 0.0"/>
      <inertia ixx="0.1" ixy="0" ixz="0" iyy="0.1" iyz="0" izz="0.1"/>
    </inertial>

    <visual>
      <origin rpy="0 0 0.0" xyz="0 0.0 0.15"/>
      <geometry>
         <mesh filename="package://irp6_description/meshes/link6.3ds" />
      </geometry>
    </visual>

    <collision>
      <origin rpy="0.0 0 0.0" xyz="0 0.0 -0.05"/>
      <geometry>
        <cylinder radius="0.1" length="0.10" />
      </geometry>
    </collision>
  </link>

  <joint name="Irp6ptfgJoint1" type="prismatic">
    <origin rpy="0 0 0" xyz="0.0 0.0 0.15"/>
    <parent link="pl_6"/>
    <child link="pl_g1"/>
    <axis xyz="0 1 0" />
    <limit upper="0.1" lower="0" effort="10" velocity=".53" />
  </joint>

  <joint name="Irp6ptfgJoint1a" type="prismatic">
    <origin rpy="0 0 0" xyz="0.0 0.0 0.15"/>
    <parent link="pl_6"/>
    <child link="pl_g2"/>
    <axis xyz="0 -1 0" />
    <limit upper="0.1" lower="0" effort="10" velocity=".53" />
    <mimic joint="Irp6ptfgJoint1" />
  </joint>


  <link name="pl_g1">
    <inertial>
      <mass value="0.1"/>
      <origin xyz="0.0 0.0 0.0"/>
      <inertia ixx="0.1" ixy="0" ixz="0" iyy="0.1" iyz="0" izz="0.1"/>
    </inertial>

    <visual>
      <origin rpy="0 0 0.0" xyz="0 0.02 0.0"/>
      <geometry>
         <box size="0.05 0.04 0.12" />
      </geometry>
    </visual>

    <collision>
      <origin rpy="0.0 0 0.0" xyz="0 0.02 0.0"/>
      <geometry>
        <box size="0.05 0.04 0.12" />
      </geometry>
    </collision>
  </link>


<link name="pl_g2">
    <inertial>
      <mass value="0.1"/>
      <origin xyz="0.0 0.0 0.0"/>
      <inertia ixx="0.1" ixy="0" ixz="0" iyy="0.1" iyz="0" izz="0.1"/>
    </inertial>

    <visual>
      <origin rpy="0 0 0.0" xyz="0 -0.02 0.0"/>
      <geometry>
         <box size="0.05 0.04 0.12" />
      </geometry>origin
    </visual>

    <collision>
      <origin rpy="0.0 0 0.0" xyz="0 -0.02 0.0"/>
      <geometry>
        <box size="0.05 0.04 0.12" />
      </geometry>
    </collision>
  </link>

<joint name="pl_camera" type="fixed">
    <origin rpy="0.0 0.0 -1.57" xyz="0.0551 0.0 0.13"/>
    <parent link="pl_6"/>
    <child link="p_c"/>
  </joint>

<link name="p_c">
</link>

<joint name="pl_camera_optical_frame" type="fixed">
    <origin rpy="0.0 0.0 3.14" xyz="0.0 0.0 0.0"/>
    <parent link="p_c"/>
    <child link="p_c_optical_frame"/>
  </joint>

<link name="p_c_optical_frame">
</link>



<!-- Kinect                       -->
<!--
  <joint name="kinect_joint" type="fixed">
    <origin rpy="0.0 0.87 1.58" xyz="0.715 -1.07 1.8"/>
    <parent link="base_link"/>
    <child link="kinect_base"/>
  </joint>

  <link name="kinect_base">
  </link>

  <joint name="kinect_depth_joint" type="fixed">
    <origin rpy="0 0.0 0" xyz="0.0 -0.02 0.0"/>
    <parent link="kinect_base"/>
    <child link="openni_depth_frame"/>
  </joint>

  <link name="openni_depth_frame">
  </link>

  <joint name="kinect_rgb_joint" type="fixed">
    <origin rpy="0 0.0 0" xyz="0.0 -0.04 0.0"/>
    <parent link="kinect_base"/>
    <child link="openni_rgb_frame"/>
  </joint>

  <link name="openni_rgb_frame">
  </link>

  <joint name="kinect_depth_optical_joint" type="fixed">
    <origin xyz="0 0.0 0" rpy="1.57 0.0 1.57"/>
    <parent link="openni_depth_frame"/>
    <child link="openni_depth_optical_frame"/>
  </joint>

  <link name="openni_depth_optical_frame">
  </link>

  <joint name="kinect_rgb_optical_joint" type="fixed">
    <origin xyz="0 0.0 0" rpy="1.57 0.0 1.57"/>
    <parent link="openni_rgb_frame"/>
    <child link="openni_rgb_optical_frame"/>
  </joint>

  <link name="openni_rgb_optical_frame">
  </link>
-->
<!--
  <joint name="laser_tilt" type="revolute">
    <origin rpy="${0.5 * M_PI} 0 0" xyz="0.0 -0.1 2.2"/>
    <axis xyz="0 0 1"/>
    <limit lower="0.0" upper="3.14" effort="10.0" velocity="10.0" />
    <parent link="base_link"/>
    <child link="laser_link"/>
  </joint>

  <link name="laser_link">
    <inertial>
      <mass value="0.1"/>
      <origin xyz="0.0 0.0 0.0"/>
      <inertia ixx="0.1" ixy="0" ixz="0" iyy="0.1" iyz="0" izz="0.1"/>
    </inertial>
  </link>
-->
</robot>
